/u/yzhang70/miniconda3/envs/pinn/lib/python3.10/site-packages/torch/utils/data/dataloader.py:617: UserWarning: This DataLoader will create 4 worker processes in total. Our suggested max number of worker in current system is 2, which is smaller than what this DataLoader is going to create. Please be aware that excessive worker creation might get DataLoader running slow or even freeze, lower the worker number to avoid potential slowness/freeze if necessary.
  warnings.warn(
Training and testing datasets ready
model =  VisionTransformer
Network ready to train
Training begins
TRAINING:
epoch: 0 loss: 6.085 acc: 0.60 time: 77.17
TESTING:
Accuracy of the network on test images: 0.77 %
Average loss on test images: 5.791
TRAINING:
epoch: 1 loss: 5.764 acc: 0.86 time: 75.05
TESTING:
Accuracy of the network on test images: 0.87 %
Average loss on test images: 5.800
TRAINING:
epoch: 2 loss: 5.664 acc: 1.23 time: 85.95
TESTING:
Accuracy of the network on test images: 2.03 %
Average loss on test images: 5.546
TRAINING:
epoch: 3 loss: 5.462 acc: 2.25 time: 85.45
TESTING:
Accuracy of the network on test images: 2.70 %
Average loss on test images: 5.413
TRAINING:
epoch: 4 loss: 5.380 acc: 2.48 time: 80.12
TESTING:
Accuracy of the network on test images: 3.86 %
Average loss on test images: 5.331
TRAINING:
epoch: 5 loss: 5.343 acc: 3.45 time: 77.79
TESTING:
Accuracy of the network on test images: 3.67 %
Average loss on test images: 5.329
TRAINING:
epoch: 6 loss: 5.329 acc: 3.51 time: 75.44
TESTING:
Accuracy of the network on test images: 3.96 %
Average loss on test images: 5.374
TRAINING:
epoch: 7 loss: 5.263 acc: 4.28 time: 77.41
TESTING:
Accuracy of the network on test images: 4.92 %
Average loss on test images: 5.245
TRAINING:
epoch: 8 loss: 5.210 acc: 4.64 time: 77.67
TESTING:
Accuracy of the network on test images: 3.47 %
Average loss on test images: 5.367
TRAINING:
epoch: 9 loss: 5.250 acc: 3.69 time: 77.94
TESTING:
Accuracy of the network on test images: 4.34 %
Average loss on test images: 5.313
TRAINING:
epoch: 10 loss: 5.201 acc: 4.52 time: 75.78
TESTING:
Accuracy of the network on test images: 3.86 %
Average loss on test images: 5.263
TRAINING:
epoch: 11 loss: 5.197 acc: 4.76 time: 78.13
TESTING:
Accuracy of the network on test images: 5.69 %
Average loss on test images: 5.204
TRAINING:
epoch: 12 loss: 5.169 acc: 5.31 time: 81.68
TESTING:
Accuracy of the network on test images: 5.89 %
Average loss on test images: 5.207
TRAINING:
epoch: 13 loss: 5.111 acc: 5.60 time: 77.59
TESTING:
Accuracy of the network on test images: 5.89 %
Average loss on test images: 5.185
TRAINING:
epoch: 14 loss: 5.080 acc: 6.28 time: 76.39
TESTING:
Accuracy of the network on test images: 6.47 %
Average loss on test images: 5.148
TRAINING:
epoch: 15 loss: 5.080 acc: 5.85 time: 79.53
TESTING:
Accuracy of the network on test images: 6.18 %
Average loss on test images: 5.215
TRAINING:
epoch: 16 loss: 5.296 acc: 4.18 time: 79.71
TESTING:
Accuracy of the network on test images: 5.60 %
Average loss on test images: 5.311
Traceback (most recent call last):
  File "/u/yzhang70/CS444-Final-Project/vit_run_128.py", line 137, in <module>
    train(
  File "/u/yzhang70/CS444-Final-Project/utils.py", line 135, in train
    for i, (imgs, labels) in enumerate(trainloader):
  File "/u/yzhang70/miniconda3/envs/pinn/lib/python3.10/site-packages/torch/utils/data/dataloader.py", line 701, in __next__
    data = self._next_data()
  File "/u/yzhang70/miniconda3/envs/pinn/lib/python3.10/site-packages/torch/utils/data/dataloader.py", line 1448, in _next_data
    idx, data = self._get_data()
  File "/u/yzhang70/miniconda3/envs/pinn/lib/python3.10/site-packages/torch/utils/data/dataloader.py", line 1412, in _get_data
    success, data = self._try_get_data()
  File "/u/yzhang70/miniconda3/envs/pinn/lib/python3.10/site-packages/torch/utils/data/dataloader.py", line 1243, in _try_get_data
    data = self._data_queue.get(timeout=timeout)
  File "/u/yzhang70/miniconda3/envs/pinn/lib/python3.10/multiprocessing/queues.py", line 122, in get
    return _ForkingPickler.loads(res)
  File "/u/yzhang70/miniconda3/envs/pinn/lib/python3.10/site-packages/torch/multiprocessing/reductions.py", line 541, in rebuild_storage_fd
    fd = df.detach()
  File "/u/yzhang70/miniconda3/envs/pinn/lib/python3.10/multiprocessing/resource_sharer.py", line 57, in detach
    with _resource_sharer.get_connection(self._id) as conn:
  File "/u/yzhang70/miniconda3/envs/pinn/lib/python3.10/multiprocessing/resource_sharer.py", line 86, in get_connection
    c = Client(address, authkey=process.current_process().authkey)
  File "/u/yzhang70/miniconda3/envs/pinn/lib/python3.10/multiprocessing/connection.py", line 502, in Client
    c = SocketClient(address)
  File "/u/yzhang70/miniconda3/envs/pinn/lib/python3.10/multiprocessing/connection.py", line 630, in SocketClient
    s.connect(address)
FileNotFoundError: [Errno 2] No such file or directory
Traceback (most recent call last):
  File "/u/yzhang70/CS444-Final-Project/vit_run_128.py", line 137, in <module>
    train(
  File "/u/yzhang70/CS444-Final-Project/utils.py", line 135, in train
    for i, (imgs, labels) in enumerate(trainloader):
  File "/u/yzhang70/miniconda3/envs/pinn/lib/python3.10/site-packages/torch/utils/data/dataloader.py", line 701, in __next__
    data = self._next_data()
  File "/u/yzhang70/miniconda3/envs/pinn/lib/python3.10/site-packages/torch/utils/data/dataloader.py", line 1448, in _next_data
    idx, data = self._get_data()
  File "/u/yzhang70/miniconda3/envs/pinn/lib/python3.10/site-packages/torch/utils/data/dataloader.py", line 1412, in _get_data
    success, data = self._try_get_data()
  File "/u/yzhang70/miniconda3/envs/pinn/lib/python3.10/site-packages/torch/utils/data/dataloader.py", line 1243, in _try_get_data
    data = self._data_queue.get(timeout=timeout)
  File "/u/yzhang70/miniconda3/envs/pinn/lib/python3.10/multiprocessing/queues.py", line 122, in get
    return _ForkingPickler.loads(res)
  File "/u/yzhang70/miniconda3/envs/pinn/lib/python3.10/site-packages/torch/multiprocessing/reductions.py", line 541, in rebuild_storage_fd
    fd = df.detach()
  File "/u/yzhang70/miniconda3/envs/pinn/lib/python3.10/multiprocessing/resource_sharer.py", line 57, in detach
    with _resource_sharer.get_connection(self._id) as conn:
  File "/u/yzhang70/miniconda3/envs/pinn/lib/python3.10/multiprocessing/resource_sharer.py", line 86, in get_connection
    c = Client(address, authkey=process.current_process().authkey)
  File "/u/yzhang70/miniconda3/envs/pinn/lib/python3.10/multiprocessing/connection.py", line 502, in Client
    c = SocketClient(address)
  File "/u/yzhang70/miniconda3/envs/pinn/lib/python3.10/multiprocessing/connection.py", line 630, in SocketClient
    s.connect(address)
FileNotFoundError: [Errno 2] No such file or directory
